           ^^^^^^^^^^^^^^^^^^^^^^^^^^

  File "/usr/local/lib/python3.11/site-packages/sqlalchemy/engine/base.py", line 1982, in _exec_single_context

    self._handle_dbapi_exception(

  File "/usr/local/lib/python3.11/site-packages/sqlalchemy/engine/base.py", line 2351, in _handle_dbapi_exception

    raise sqlalchemy_exception.with_traceback(exc_info[2]) from e

  File "/usr/local/lib/python3.11/site-packages/sqlalchemy/engine/base.py", line 1963, in _exec_single_context

    self.dialect.do_execute(

  File "/usr/local/lib/python3.11/site-packages/sqlalchemy/engine/default.py", line 943, in do_execute

[2025-06-13 03:03:54 +0000] [1] [ERROR] Worker (pid:2) exited with code 3

[2025-06-13 03:03:54 +0000] [1] [ERROR] Shutting down: Master

[2025-06-13 03:03:54 +0000] [1] [ERROR] Reason: Worker failed to boot.

[2025-06-13 03:03:55 +0000] [1] [INFO] Starting gunicorn 23.0.0

[2025-06-13 03:03:55 +0000] [1] [INFO] Listening at: http://0.0.0.0:5000 (1)

[2025-06-13 03:03:55 +0000] [1] [INFO] Using worker: sync

[2025-06-13 03:03:55 +0000] [2] [INFO] Booting worker with pid: 2

[2025-06-13 03:03:56 +0000] [2] [ERROR] Exception in worker process

Traceback (most recent call last):

  File "/usr/local/lib/python3.11/site-packages/sqlalchemy/engine/base.py", line 1963, in _exec_single_context

    self.dialect.do_execute(

  File "/usr/local/lib/python3.11/site-packages/sqlalchemy/engine/default.py", line 943, in do_execute

    cursor.execute(statement, parameters)

sqlite3.OperationalError: no such table: information_schema.columns

 

The above exception was the direct cause of the following exception:

 

Traceback (most recent call last):

  File "/usr/local/lib/python3.11/site-packages/gunicorn/arbiter.py", line 608, in spawn_worker

    worker.init_process()

  File "/usr/local/lib/python3.11/site-packages/gunicorn/workers/base.py", line 135, in init_process

    self.load_wsgi()

  File "/usr/local/lib/python3.11/site-packages/gunicorn/workers/base.py", line 147, in load_wsgi

    self.wsgi = self.app.wsgi()

                ^^^^^^^^^^^^^^^

  File "/usr/local/lib/python3.11/site-packages/gunicorn/app/base.py", line 66, in wsgi

    self.callable = self.load()

                    ^^^^^^^^^^^

  File "/usr/local/lib/python3.11/site-packages/gunicorn/app/wsgiapp.py", line 57, in load

    return self.load_wsgiapp()

           ^^^^^^^^^^^^^^^^^^^

  File "/usr/local/lib/python3.11/site-packages/gunicorn/app/wsgiapp.py", line 47, in load_wsgiapp

    return util.import_app(self.app_uri)

           ^^^^^^^^^^^^^^^^^^^^^^^^^^^^^

  File "/usr/local/lib/python3.11/site-packages/gunicorn/util.py", line 370, in import_app

    mod = importlib.import_module(module)

          ^^^^^^^^^^^^^^^^^^^^^^^^^^^^^^^

  File "/usr/local/lib/python3.11/importlib/__init__.py", line 126, in import_module

    return _bootstrap._gcd_import(name[level:], package, level)

           ^^^^^^^^^^^^^^^^^^^^^^^^^^^^^^^^^^^^^^^^^^^^^^^^^^^^

  File "<frozen importlib._bootstrap>", line 1204, in _gcd_import

  File "<frozen importlib._bootstrap>", line 1176, in _find_and_load

  File "<frozen importlib._bootstrap>", line 1147, in _find_and_load_unlocked

  File "<frozen importlib._bootstrap>", line 690, in _load_unlocked

  File "<frozen importlib._bootstrap_external>", line 940, in exec_module

  File "<frozen importlib._bootstrap>", line 241, in _call_with_frames_removed

  File "/app/app.py", line 51, in <module>

    result = conn.execute(text("""

             ^^^^^^^^^^^^^^^^^^^^^